#VRML_SIM R2023a utf8

EXTERNPROTO "https://raw.githubusercontent.com/cyberbotics/webots/R2023a/projects/objects/backgrounds/protos/TexturedBackground.proto"
EXTERNPROTO "https://raw.githubusercontent.com/cyberbotics/webots/R2023a/projects/objects/backgrounds/protos/TexturedBackgroundLight.proto"
EXTERNPROTO "https://raw.githubusercontent.com/cyberbotics/webots/R2023a/projects/objects/floors/protos/RectangleArena.proto"
EXTERNPROTO "https://raw.githubusercontent.com/cyberbotics/webots/R2023a/projects/robots/nvidia/jetbot/protos/JetBotRaspberryPiCamera.proto"

WorldInfo {
}
Viewpoint {
  orientation -0.0899020991709661 0.09080822142314719 0.9918021372666115 1.5690308951341525
  position -2.3660203181394794 -0.8258497378237457 0.2038598044312396
  follow "robot"
}
TexturedBackground {
}
TexturedBackgroundLight {
}
RectangleArena {
  floorSize 10 10
  floorAppearance PBRAppearance {
    roughness 1
    roughnessMap ImageTexture {
      url [
        "https://raw.githubusercontent.com/cyberbotics/webots/R2023a/projects/appearances/protos/textures/parquetry/chequered_parquetry_roughness.jpg"
      ]
    }
    metalness 0
    normalMap ImageTexture {
      url [
        "https://raw.githubusercontent.com/cyberbotics/webots/R2023a/projects/appearances/protos/textures/parquetry/chequered_parquetry_normal.jpg"
      ]
    }
    occlusionMap ImageTexture {
      url [
        "https://raw.githubusercontent.com/cyberbotics/webots/R2023a/projects/appearances/protos/textures/parquetry/chequered_parquetry_occlusion.jpg"
      ]
    }
  }
}
Robot {
  translation -2.4814 -0.00444268 0.0384526
  rotation -9.377910065551063e-05 -7.840970439123778e-05 -0.9999999925286992 1.7498898677577823
  children [
    DEF base Shape {
      appearance PBRAppearance {
        baseColor 0.333333 0 0
        metalness 0
      }
      geometry Box {
        size 0.1 0.2 0.01
      }
    }
    DEF leftWheel1 HingeJoint {
      jointParameters HingeJointParameters {
        position 102.52146099041711
        axis -1 0 0
        anchor -0.058 0.06 -0.010000000000000002
      }
      device [
        RotationalMotor {
          name "L1"
          maxVelocity 100
          maxTorque 40
        }
      ]
      endPoint Solid {
        translation -0.05816302481200897 0.059791356426400856 -0.010163978697827822
        rotation -0.5813055625197168 -0.5692107215895252 -0.5814490497121545 4.176394421731588
        children [
          DEF wheel Shape {
            appearance PBRAppearance {
              baseColor 0 0 0
            }
            geometry Cylinder {
              height 0.015
              radius 0.03
            }
          }
        ]
        boundingObject USE wheel
        physics Physics {
          mass 2
        }
      }
    }
    DEF RightWheel1 HingeJoint {
      jointParameters HingeJointParameters {
        position 92.5882012852185
        axis -1 0 0
        anchor 0.0575 0.06 -0.010022
      }
      device [
        RotationalMotor {
          name "R1"
          maxVelocity 100
          maxTorque 40
        }
      ]
      endPoint Solid {
        translation 0.0575 0.06 -0.010022
        rotation -0.5936144975902693 -0.5432311545537465 -0.5937354132716489 4.136684904064738
        children [
          DEF wheel Shape {
            appearance PBRAppearance {
              baseColor 0 0 0
            }
            geometry Cylinder {
              height 0.015
              radius 0.03
            }
          }
        ]
        name "solid(1)"
        boundingObject USE wheel
        physics Physics {
          mass 2
        }
      }
    }
    DEF leftWheel2 HingeJoint {
      jointParameters HingeJointParameters {
        position 92.58822890393972
        axis -1 0 0
        anchor 0.0575 -0.06 -0.010022
      }
      device [
        DEF R2 RotationalMotor {
          name "R2"
          maxVelocity 100
          maxTorque 40
        }
      ]
      endPoint Solid {
        translation 0.05749985079968464 -0.06000078451666273 -0.010022082238631496
        rotation 0.6256858774456295 0.4656980955973221 0.6258134438649591 2.270085715601062
        children [
          DEF wheel Shape {
            appearance PBRAppearance {
              baseColor 0 0 0
            }
            geometry Cylinder {
              height 0.015
              radius 0.03
            }
          }
        ]
        name "solid(2)"
        boundingObject USE wheel
        physics Physics {
          mass 2
        }
      }
    }
    DEF leftWheel2 HingeJoint {
      jointParameters HingeJointParameters {
        position 102.52148789218363
        axis -1 0 0
        anchor -0.058 -0.06 -0.01
      }
      device [
        RotationalMotor {
          name "L2"
          maxVelocity 100
          maxTorque 40
        }
      ]
      endPoint Solid {
        translation -0.058 -0.06 -0.01
        rotation -0.6426216161994964 0.4170211789704949 -0.6427525143344096 2.3515510471901226
        children [
          DEF wheel Shape {
            appearance PBRAppearance {
              baseColor 0 0 0
            }
            geometry Cylinder {
              height 0.015
              radius 0.03
            }
          }
        ]
        name "solid(3)"
        boundingObject USE wheel
        physics Physics {
          mass 2
        }
      }
    }
    DistanceSensor {
      translation 0.0474 0.1 -0.0100081
      rotation 0.2505660186413608 0.9351250695705025 0.25051501863756653 1.63802
      children [
        Shape {
          appearance PBRAppearance {
            baseColor 0.333333 0.666667 1
          }
          geometry Box {
            size 0.02 0.005 0.005
          }
        }
      ]
      name "IR1"
      type "infra-red"
    }
    DistanceSensor {
      translation 0.019998 0.1 -0.0100041
      rotation 0.2505660186413608 0.9351250695705025 0.25051501863756653 1.63802
      children [
        Shape {
          appearance PBRAppearance {
            baseColor 0.333333 0.666667 1
          }
          geometry Box {
            size 0.02 0.005 0.005
          }
        }
      ]
      name "IR2"
      type "infra-red"
    }
    DistanceSensor {
      translation -1.99979e-06 0.1 -0.0100001
      rotation 0 1 0 1.571
      children [
        Shape {
          appearance PBRAppearance {
            baseColor 0.333333 0.666667 1
          }
          geometry Box {
            size 0.02 0.005 0.005
          }
        }
      ]
      name "IR3"
      type "infra-red"
    }
    DistanceSensor {
      translation -0.020002 0.1 -0.00999602
      rotation 0.2505660186413608 0.9351250695705025 0.25051501863756653 1.63802
      children [
        Shape {
          appearance PBRAppearance {
            baseColor 0.333333 0.666667 1
          }
          geometry Box {
            size 0.02 0.005 0.005
          }
        }
      ]
      name "IR4"
      type "infra-red"
    }
    DistanceSensor {
      translation -0.0474 0.1 -0.00999194
      rotation 0.2505660186413608 0.9351250695705025 0.25051501863756653 1.63802
      children [
        Shape {
          appearance PBRAppearance {
            baseColor 0.333333 0.666667 1
          }
          geometry Box {
            size 0.02 0.005 0.005
          }
        }
      ]
      name "IR5"
      type "infra-red"
    }
    DEF link1 HingeJoint {
      jointParameters HingeJointParameters {
        axis 0 0 1
        anchor 0 0 0.02
        minStop -1.5
        maxStop 1.5
      }
      device [
        RotationalMotor {
          name "link1"
          minPosition -1.5
          maxPosition 1.5
        }
      ]
      endPoint Solid {
        translation 0 0 0.02
        children [
          DEF link1 Shape {
            appearance PBRAppearance {
              roughness 1
              metalness 0
            }
            geometry Cylinder {
              height 0.04
              radius 0.015
            }
          }
          DEF link2 HingeJoint {
            jointParameters HingeJointParameters {
              position 0.5
              anchor -0.019999999999999997 5.194559690134771e-10 -2.0367299337579085e-06
              minStop -1.3
              maxStop 0.6
            }
            device [
              RotationalMotor {
                name "joint1"
                minPosition -1.3
                maxPosition 0.6
              }
            ]
            endPoint DEF joint1 Solid {
              translation -0.020000063554223936 -3.217843157466286e-08 -3.677961582240655e-06
              rotation 0.11803697737839201 -0.9859778110388496 -0.11796197739276616 1.5847253071795835
              children [
                DEF joint1 Shape {
                  appearance PBRAppearance {
                    baseColor 0 0 0
                    roughness 1
                  }
                  geometry Cylinder {
                    height 0.025
                    radius 0.008
                  }
                }
                DEF link2 Slot {
                  endPoint DEF link Slot {
                    endPoint DEF link2 Solid {
                      translation 0.040002 -1.1289e-07 0.0099921
                      rotation 1.88136e-06 1 -9.76365e-13 -1.5705953071795866
                      children [
                        DEF link2 Shape {
                          appearance PBRAppearance {
                            baseColor 0 0 0.498039
                            roughness 1
                            metalness 0
                          }
                          geometry Cylinder {
                            height 0.1
                            radius 0.01
                          }
                        }
                        DEF link3 HingeJoint {
                          jointParameters HingeJointParameters {
                            position 0.4
                            anchor -0.02 1.87713e-07 -0.04
                            minStop -1
                            maxStop 1
                          }
                          device [
                            RotationalMotor {
                              name "joint2"
                              minPosition -1
                              maxPosition 1
                            }
                          ]
                          endPoint Solid {
                            translation -0.02 1.87713e-07 -0.04
                            rotation 0.06888378160766538 -0.9952437342646387 -0.06888348160774516 1.5755553071795845
                            children [
                              DEF joint2 Shape {
                                appearance PBRAppearance {
                                  baseColor 0 0 0
                                  roughness 1
                                }
                                geometry Cylinder {
                                  height 0.02
                                  radius 0.008
                                }
                              }
                              DEF link3 Slot {
                                endPoint DEF link3 Slot {
                                  endPoint Solid {
                                    translation 0 0.04 0.01
                                    rotation 1 0 0 -1.5707953071795862
                                    children [
                                      DEF link3 Shape {
                                        appearance PBRAppearance {
                                          baseColor 0 0 0.498039
                                          roughness 1
                                          metalness 0
                                        }
                                        geometry Cylinder {
                                          height 0.1
                                          radius 0.01
                                        }
                                      }
                                      DEF gripper HingeJoint {
                                        jointParameters HingeJointParameters {
                                          axis 0 0 1
                                          anchor 0 0 0.05
                                          minStop -1.5
                                          maxStop 1.5
                                        }
                                        device [
                                          DEF gripperJoint RotationalMotor {
                                            name "gripperJoint"
                                            minPosition -1.5
                                            maxPosition 1.5
                                          }
                                        ]
                                        endPoint Solid {
                                          translation 0 0 0.05
                                          children [
                                            DEF gripperjoint Shape {
                                              appearance PBRAppearance {
                                                baseColor 0.666667 0 0
                                                roughness 1
                                                metalness 0
                                              }
                                              geometry Box {
                                                size 0.025 0.08 0.01
                                              }
                                            }
                                            DEF gripper1 HingeJoint {
                                              jointParameters HingeJointParameters {
                                                anchor -6.11019e-06 0.04 2.07414e-10
                                                minStop -3
                                                maxStop 3
                                              }
                                              device [
                                                RotationalMotor {
                                                  name "gripperJoint1"
                                                  minPosition -3
                                                  maxPosition 3
                                                }
                                              ]
                                              endPoint Solid {
                                                translation -6.11019e-06 0.04 2.07414e-10
                                                rotation -0.35741498412630757 0.8628779616774335 -0.35734598412937174 1.7179453071795856
                                                children [
                                                  DEF gripperJoint1 Shape {
                                                    appearance PBRAppearance {
                                                      baseColor 0 0 0
                                                      roughness 1
                                                    }
                                                    geometry Cylinder {
                                                      height 0.03
                                                      radius 0.004
                                                    }
                                                  }
                                                  Slot {
                                                    endPoint Slot {
                                                      endPoint Solid {
                                                        translation -0.03 0 0
                                                        rotation 0 1 0 0
                                                        children [
                                                          DEF gripperjoint1 Shape {
                                                            appearance PBRAppearance {
                                                              baseColor 0.666667 0 0
                                                              roughness 1
                                                              metalness 0
                                                            }
                                                            geometry Box {
                                                              size 0.05 0.005 0.02
                                                            }
                                                          }
                                                        ]
                                                        boundingObject USE gripperjoint1
                                                        physics Physics {
                                                        }
                                                      }
                                                    }
                                                  }
                                                  Slot {
                                                    endPoint Slot {
                                                      endPoint Solid {
                                                        translation -0.05 -0.005 0
                                                        rotation 0 0 1 -0.261795307179586
                                                        children [
                                                          DEF grip2 Shape {
                                                            appearance PBRAppearance {
                                                              baseColor 0 0 0
                                                            }
                                                            geometry Box {
                                                              size 0.03 0.005 0.02
                                                            }
                                                          }
                                                        ]
                                                        name "solid(1)"
                                                        boundingObject USE grip2
                                                        physics Physics {
                                                        }
                                                      }
                                                    }
                                                  }
                                                ]
                                                boundingObject USE gripperJoint1
                                                physics Physics {
                                                }
                                              }
                                            }
                                            DEF gripper2 HingeJoint {
                                              jointParameters HingeJointParameters {
                                                anchor -2.03695e-12 -0.04 2.07414e-10
                                                minStop -3
                                                maxStop 3
                                              }
                                              device [
                                                RotationalMotor {
                                                  name "gripperJoint2"
                                                  minPosition -3
                                                  maxPosition 3
                                                }
                                              ]
                                              endPoint Solid {
                                                translation -2.03695e-12 -0.04 2.07414e-10
                                                rotation 0.3574158034154647 0.8628785254027042 0.357343803455066 1.71795
                                                children [
                                                  USE gripperJoint1
                                                  Slot {
                                                    endPoint Slot {
                                                      endPoint Solid {
                                                        translation -0.03 0 0
                                                        children [
                                                          USE gripperjoint1
                                                        ]
                                                        boundingObject USE gripperjoint1
                                                        physics Physics {
                                                        }
                                                      }
                                                    }
                                                  }
                                                  Slot {
                                                    endPoint Slot {
                                                      endPoint Solid {
                                                        translation -0.0474118 0.00465927 0
                                                        rotation 0 0 1 0.261803
                                                        children [
                                                          DEF grip Shape {
                                                            appearance PBRAppearance {
                                                              baseColor 0 0 0
                                                            }
                                                            geometry Box {
                                                              size 0.03 0.005 0.02
                                                            }
                                                          }
                                                        ]
                                                        name "solid(1)"
                                                        boundingObject USE grip
                                                        physics Physics {
                                                        }
                                                      }
                                                    }
                                                  }
                                                ]
                                                name "solid(1)"
                                                boundingObject USE gripperJoint1
                                                physics Physics {
                                                }
                                              }
                                            }
                                          ]
                                          boundingObject USE gripperjoint
                                          physics Physics {
                                          }
                                        }
                                      }
                                    ]
                                    boundingObject USE link3
                                    physics Physics {
                                    }
                                  }
                                }
                              }
                            ]
                            boundingObject USE joint2
                            physics Physics {
                            }
                          }
                        }
                      ]
                      boundingObject USE link2
                      physics Physics {
                      }
                    }
                  }
                }
              ]
              boundingObject USE joint1
              physics Physics {
              }
            }
          }
        ]
        name "solid(4)"
        boundingObject USE link1
        physics Physics {
        }
      }
    }
    JetBotRaspberryPiCamera {
      translation -4.37999e-13 0.0999982 0.0160001
      rotation -0.12943196975110505 0.12943096975133875 -0.9831047702435265 -1.5878253071795863
      fieldOfView 2.5
    }
    DistanceSensor {
      translation 2.03673e-06 0.1 0
      rotation 0 0 1 1.571
      children [
        Shape {
          appearance PBRAppearance {
            baseColor 0 0 0
          }
          geometry Box {
            size 0.005 0.025 0.005
          }
        }
      ]
      name "dstSensor"
    }
    DistanceSensor {
      translation -0.049982 -0.010014 0
      rotation 0 0 1 3.14159
      children [
        Shape {
          appearance PBRAppearance {
            baseColor 0 0 0
          }
          geometry Box {
            size 0.005 0.025 0.005
          }
        }
      ]
      name "dstSensor1"
    }
  ]
  boundingObject USE base
  physics Physics {
  }
  controller "linefollowercontroller"
}
Solid {
  translation -2.23 -0.01 0.001
  children [
    Shape {
      appearance PBRAppearance {
        baseColor 0 0 0
        roughness 1
        roughnessMap ImageTexture {
          url [
            "https://raw.githubusercontent.com/cyberbotics/webots/R2023a/projects/appearances/protos/textures/parquetry/chequered_parquetry_roughness.jpg"
          ]
        }
        metalness 0
        normalMap ImageTexture {
          url [
            "https://raw.githubusercontent.com/cyberbotics/webots/R2023a/projects/appearances/protos/textures/parquetry/chequered_parquetry_normal.jpg"
          ]
        }
        occlusionMap ImageTexture {
          url [
            "https://raw.githubusercontent.com/cyberbotics/webots/R2023a/projects/appearances/protos/textures/parquetry/chequered_parquetry_occlusion.jpg"
          ]
        }
      }
      geometry Plane {
        size 1 0.025
      }
    }
  ]
}
Solid {
  translation -1.63611 -0.108995 0.001
  rotation 0 0 -1 0.785396
  children [
    Shape {
      appearance PBRAppearance {
        baseColor 0 0 0
        roughness 1
        roughnessMap ImageTexture {
          url [
            "https://raw.githubusercontent.com/cyberbotics/webots/R2023a/projects/appearances/protos/textures/parquetry/chequered_parquetry_roughness.jpg"
          ]
        }
        metalness 0
        normalMap ImageTexture {
          url [
            "https://raw.githubusercontent.com/cyberbotics/webots/R2023a/projects/appearances/protos/textures/parquetry/chequered_parquetry_normal.jpg"
          ]
        }
        occlusionMap ImageTexture {
          url [
            "https://raw.githubusercontent.com/cyberbotics/webots/R2023a/projects/appearances/protos/textures/parquetry/chequered_parquetry_occlusion.jpg"
          ]
        }
      }
      geometry Plane {
        size 0.3 0.025
      }
    }
  ]
  name "solid(1)"
}
Solid {
  translation -1.38611 -0.208995 0.001
  rotation 0 0 1 2.16103e-06
  children [
    Shape {
      appearance PBRAppearance {
        baseColor 0 0 0
        roughness 1
        roughnessMap ImageTexture {
          url [
            "https://raw.githubusercontent.com/cyberbotics/webots/R2023a/projects/appearances/protos/textures/parquetry/chequered_parquetry_roughness.jpg"
          ]
        }
        metalness 0
        normalMap ImageTexture {
          url [
            "https://raw.githubusercontent.com/cyberbotics/webots/R2023a/projects/appearances/protos/textures/parquetry/chequered_parquetry_normal.jpg"
          ]
        }
        occlusionMap ImageTexture {
          url [
            "https://raw.githubusercontent.com/cyberbotics/webots/R2023a/projects/appearances/protos/textures/parquetry/chequered_parquetry_occlusion.jpg"
          ]
        }
      }
      geometry Plane {
        size 0.3 0.025
      }
    }
  ]
  name "solid(2)"
}
Solid {
  translation -1.15194 -0.114768 0.001
  rotation 0 0 1 0.785404
  children [
    Shape {
      appearance PBRAppearance {
        baseColor 0 0 0
        roughness 1
        roughnessMap ImageTexture {
          url [
            "https://raw.githubusercontent.com/cyberbotics/webots/R2023a/projects/appearances/protos/textures/parquetry/chequered_parquetry_roughness.jpg"
          ]
        }
        metalness 0
        normalMap ImageTexture {
          url [
            "https://raw.githubusercontent.com/cyberbotics/webots/R2023a/projects/appearances/protos/textures/parquetry/chequered_parquetry_normal.jpg"
          ]
        }
        occlusionMap ImageTexture {
          url [
            "https://raw.githubusercontent.com/cyberbotics/webots/R2023a/projects/appearances/protos/textures/parquetry/chequered_parquetry_occlusion.jpg"
          ]
        }
      }
      geometry Plane {
        size 0.3 0.025
      }
    }
  ]
  name "solid(3)"
}
Solid {
  translation -0.91611 -0.018995 0.001
  rotation 0 0 1 2.16103e-06
  children [
    Shape {
      appearance PBRAppearance {
        baseColor 0 0 0
        roughness 1
        roughnessMap ImageTexture {
          url [
            "https://raw.githubusercontent.com/cyberbotics/webots/R2023a/projects/appearances/protos/textures/parquetry/chequered_parquetry_roughness.jpg"
          ]
        }
        metalness 0
        normalMap ImageTexture {
          url [
            "https://raw.githubusercontent.com/cyberbotics/webots/R2023a/projects/appearances/protos/textures/parquetry/chequered_parquetry_normal.jpg"
          ]
        }
        occlusionMap ImageTexture {
          url [
            "https://raw.githubusercontent.com/cyberbotics/webots/R2023a/projects/appearances/protos/textures/parquetry/chequered_parquetry_occlusion.jpg"
          ]
        }
      }
      geometry Plane {
        size 0.3 0.025
      }
    }
  ]
  name "solid(4)"
}
Solid {
  translation -0.77611 -0.158995 0.001
  rotation 0 0 1 -1.5707953071795862
  children [
    Shape {
      appearance PBRAppearance {
        baseColor 0 0 0
        roughness 1
        roughnessMap ImageTexture {
          url [
            "https://raw.githubusercontent.com/cyberbotics/webots/R2023a/projects/appearances/protos/textures/parquetry/chequered_parquetry_roughness.jpg"
          ]
        }
        metalness 0
        normalMap ImageTexture {
          url [
            "https://raw.githubusercontent.com/cyberbotics/webots/R2023a/projects/appearances/protos/textures/parquetry/chequered_parquetry_normal.jpg"
          ]
        }
        occlusionMap ImageTexture {
          url [
            "https://raw.githubusercontent.com/cyberbotics/webots/R2023a/projects/appearances/protos/textures/parquetry/chequered_parquetry_occlusion.jpg"
          ]
        }
      }
      geometry Plane {
        size 0.3 0.025
      }
    }
  ]
  name "solid(5)"
}
Solid {
  translation -0.87441 -0.387731 0.001
  rotation 0 0 1 0.785399
  children [
    Shape {
      appearance PBRAppearance {
        baseColor 0 0 0
        roughness 1
        roughnessMap ImageTexture {
          url [
            "https://raw.githubusercontent.com/cyberbotics/webots/R2023a/projects/appearances/protos/textures/parquetry/chequered_parquetry_roughness.jpg"
          ]
        }
        metalness 0
        normalMap ImageTexture {
          url [
            "https://raw.githubusercontent.com/cyberbotics/webots/R2023a/projects/appearances/protos/textures/parquetry/chequered_parquetry_normal.jpg"
          ]
        }
        occlusionMap ImageTexture {
          url [
            "https://raw.githubusercontent.com/cyberbotics/webots/R2023a/projects/appearances/protos/textures/parquetry/chequered_parquetry_occlusion.jpg"
          ]
        }
      }
      geometry Plane {
        size 0.3 0.025
      }
    }
  ]
  name "solid(6)"
}
Solid {
  translation -0.879511 -0.582752 0.001
  rotation 0 0 -1 0.785396
  children [
    Shape {
      appearance PBRAppearance {
        baseColor 0 0 0
        roughness 1
        roughnessMap ImageTexture {
          url [
            "https://raw.githubusercontent.com/cyberbotics/webots/R2023a/projects/appearances/protos/textures/parquetry/chequered_parquetry_roughness.jpg"
          ]
        }
        metalness 0
        normalMap ImageTexture {
          url [
            "https://raw.githubusercontent.com/cyberbotics/webots/R2023a/projects/appearances/protos/textures/parquetry/chequered_parquetry_normal.jpg"
          ]
        }
        occlusionMap ImageTexture {
          url [
            "https://raw.githubusercontent.com/cyberbotics/webots/R2023a/projects/appearances/protos/textures/parquetry/chequered_parquetry_occlusion.jpg"
          ]
        }
      }
      geometry Plane {
        size 0.3 0.025
      }
    }
  ]
  name "solid(7)"
}
Solid {
  translation -0.683493 -0.578648 0.001
  rotation 0 0 1 0.785399
  children [
    Shape {
      appearance PBRAppearance {
        baseColor 0 0 0
        roughness 1
        roughnessMap ImageTexture {
          url [
            "https://raw.githubusercontent.com/cyberbotics/webots/R2023a/projects/appearances/protos/textures/parquetry/chequered_parquetry_roughness.jpg"
          ]
        }
        metalness 0
        normalMap ImageTexture {
          url [
            "https://raw.githubusercontent.com/cyberbotics/webots/R2023a/projects/appearances/protos/textures/parquetry/chequered_parquetry_normal.jpg"
          ]
        }
        occlusionMap ImageTexture {
          url [
            "https://raw.githubusercontent.com/cyberbotics/webots/R2023a/projects/appearances/protos/textures/parquetry/chequered_parquetry_occlusion.jpg"
          ]
        }
      }
      geometry Plane {
        size 0.3 0.025
      }
    }
  ]
  name "solid(8)"
}
Solid {
  translation -0.43611 -0.468995 0.001
  rotation 0 0 1 2.16103e-06
  children [
    Shape {
      appearance PBRAppearance {
        baseColor 0 0 0
        roughness 1
        roughnessMap ImageTexture {
          url [
            "https://raw.githubusercontent.com/cyberbotics/webots/R2023a/projects/appearances/protos/textures/parquetry/chequered_parquetry_roughness.jpg"
          ]
        }
        metalness 0
        normalMap ImageTexture {
          url [
            "https://raw.githubusercontent.com/cyberbotics/webots/R2023a/projects/appearances/protos/textures/parquetry/chequered_parquetry_normal.jpg"
          ]
        }
        occlusionMap ImageTexture {
          url [
            "https://raw.githubusercontent.com/cyberbotics/webots/R2023a/projects/appearances/protos/textures/parquetry/chequered_parquetry_occlusion.jpg"
          ]
        }
      }
      geometry Plane {
        size 0.3 0.025
      }
    }
  ]
  name "solid(9)"
}
Solid {
  translation -0.29611 -0.608995 0.001
  rotation 0 0 1 -1.5707953071795862
  children [
    Shape {
      appearance PBRAppearance {
        baseColor 0 0 0
        roughness 1
        roughnessMap ImageTexture {
          url [
            "https://raw.githubusercontent.com/cyberbotics/webots/R2023a/projects/appearances/protos/textures/parquetry/chequered_parquetry_roughness.jpg"
          ]
        }
        metalness 0
        normalMap ImageTexture {
          url [
            "https://raw.githubusercontent.com/cyberbotics/webots/R2023a/projects/appearances/protos/textures/parquetry/chequered_parquetry_normal.jpg"
          ]
        }
        occlusionMap ImageTexture {
          url [
            "https://raw.githubusercontent.com/cyberbotics/webots/R2023a/projects/appearances/protos/textures/parquetry/chequered_parquetry_occlusion.jpg"
          ]
        }
      }
      geometry Plane {
        size 0.3 0.025
      }
    }
  ]
  name "solid(10)"
}
Solid {
  translation -0.407724 -0.854417 0.001
  rotation 0 0 1 0.785399
  children [
    Shape {
      appearance PBRAppearance {
        baseColor 0 0 0
        roughness 1
        roughnessMap ImageTexture {
          url [
            "https://raw.githubusercontent.com/cyberbotics/webots/R2023a/projects/appearances/protos/textures/parquetry/chequered_parquetry_roughness.jpg"
          ]
        }
        metalness 0
        normalMap ImageTexture {
          url [
            "https://raw.githubusercontent.com/cyberbotics/webots/R2023a/projects/appearances/protos/textures/parquetry/chequered_parquetry_normal.jpg"
          ]
        }
        occlusionMap ImageTexture {
          url [
            "https://raw.githubusercontent.com/cyberbotics/webots/R2023a/projects/appearances/protos/textures/parquetry/chequered_parquetry_occlusion.jpg"
          ]
        }
      }
      geometry Plane {
        size 0.3 0.025
      }
    }
  ]
  name "solid(11)"
}
Solid {
  translation -0.65611 -0.958995 0.001
  rotation 0 0 1 2.16103e-06
  children [
    Shape {
      appearance PBRAppearance {
        baseColor 0 0 0
        roughness 1
        roughnessMap ImageTexture {
          url [
            "https://raw.githubusercontent.com/cyberbotics/webots/R2023a/projects/appearances/protos/textures/parquetry/chequered_parquetry_roughness.jpg"
          ]
        }
        metalness 0
        normalMap ImageTexture {
          url [
            "https://raw.githubusercontent.com/cyberbotics/webots/R2023a/projects/appearances/protos/textures/parquetry/chequered_parquetry_normal.jpg"
          ]
        }
        occlusionMap ImageTexture {
          url [
            "https://raw.githubusercontent.com/cyberbotics/webots/R2023a/projects/appearances/protos/textures/parquetry/chequered_parquetry_occlusion.jpg"
          ]
        }
      }
      geometry Plane {
        size 0.3 0.025
      }
    }
  ]
  name "solid(12)"
}
Solid {
  translation -0.917795 -0.882912 0.001
  rotation 0 0 -1 0.523597
  children [
    Shape {
      appearance PBRAppearance {
        baseColor 0 0 0
        roughness 1
        roughnessMap ImageTexture {
          url [
            "https://raw.githubusercontent.com/cyberbotics/webots/R2023a/projects/appearances/protos/textures/parquetry/chequered_parquetry_roughness.jpg"
          ]
        }
        metalness 0
        normalMap ImageTexture {
          url [
            "https://raw.githubusercontent.com/cyberbotics/webots/R2023a/projects/appearances/protos/textures/parquetry/chequered_parquetry_normal.jpg"
          ]
        }
        occlusionMap ImageTexture {
          url [
            "https://raw.githubusercontent.com/cyberbotics/webots/R2023a/projects/appearances/protos/textures/parquetry/chequered_parquetry_occlusion.jpg"
          ]
        }
      }
      geometry Plane {
        size 0.3 0.025
      }
    }
  ]
  name "solid(13)"
}
Solid {
  translation -1.14309 -0.910985 0.001
  rotation 0 0 1 0.785399
  children [
    Shape {
      appearance PBRAppearance {
        baseColor 0 0 0
        roughness 1
        roughnessMap ImageTexture {
          url [
            "https://raw.githubusercontent.com/cyberbotics/webots/R2023a/projects/appearances/protos/textures/parquetry/chequered_parquetry_roughness.jpg"
          ]
        }
        metalness 0
        normalMap ImageTexture {
          url [
            "https://raw.githubusercontent.com/cyberbotics/webots/R2023a/projects/appearances/protos/textures/parquetry/chequered_parquetry_normal.jpg"
          ]
        }
        occlusionMap ImageTexture {
          url [
            "https://raw.githubusercontent.com/cyberbotics/webots/R2023a/projects/appearances/protos/textures/parquetry/chequered_parquetry_occlusion.jpg"
          ]
        }
      }
      geometry Plane {
        size 0.3 0.025
      }
    }
  ]
  name "solid(14)"
}
Solid {
  translation -1.38611 -1.01899 0.001
  rotation 0 0 1 2.16103e-06
  children [
    Shape {
      appearance PBRAppearance {
        baseColor 0 0 0
        roughness 1
        roughnessMap ImageTexture {
          url [
            "https://raw.githubusercontent.com/cyberbotics/webots/R2023a/projects/appearances/protos/textures/parquetry/chequered_parquetry_roughness.jpg"
          ]
        }
        metalness 0
        normalMap ImageTexture {
          url [
            "https://raw.githubusercontent.com/cyberbotics/webots/R2023a/projects/appearances/protos/textures/parquetry/chequered_parquetry_normal.jpg"
          ]
        }
        occlusionMap ImageTexture {
          url [
            "https://raw.githubusercontent.com/cyberbotics/webots/R2023a/projects/appearances/protos/textures/parquetry/chequered_parquetry_occlusion.jpg"
          ]
        }
      }
      geometry Plane {
        size 0.3 0.025
      }
    }
  ]
  name "solid(15)"
}
Solid {
  translation -1.53611 -0.878995 0.001
  rotation 0 0 1 -1.5707953071795862
  children [
    Shape {
      appearance PBRAppearance {
        baseColor 0 0 0
        roughness 1
        roughnessMap ImageTexture {
          url [
            "https://raw.githubusercontent.com/cyberbotics/webots/R2023a/projects/appearances/protos/textures/parquetry/chequered_parquetry_roughness.jpg"
          ]
        }
        metalness 0
        normalMap ImageTexture {
          url [
            "https://raw.githubusercontent.com/cyberbotics/webots/R2023a/projects/appearances/protos/textures/parquetry/chequered_parquetry_normal.jpg"
          ]
        }
        occlusionMap ImageTexture {
          url [
            "https://raw.githubusercontent.com/cyberbotics/webots/R2023a/projects/appearances/protos/textures/parquetry/chequered_parquetry_occlusion.jpg"
          ]
        }
      }
      geometry Plane {
        size 0.3 0.025
      }
    }
  ]
  name "solid(16)"
}
Solid {
  translation -2.03 -0.74 0.001
  children [
    Shape {
      appearance PBRAppearance {
        baseColor 0 0 0
        roughness 1
        roughnessMap ImageTexture {
          url [
            "https://raw.githubusercontent.com/cyberbotics/webots/R2023a/projects/appearances/protos/textures/parquetry/chequered_parquetry_roughness.jpg"
          ]
        }
        metalness 0
        normalMap ImageTexture {
          url [
            "https://raw.githubusercontent.com/cyberbotics/webots/R2023a/projects/appearances/protos/textures/parquetry/chequered_parquetry_normal.jpg"
          ]
        }
        occlusionMap ImageTexture {
          url [
            "https://raw.githubusercontent.com/cyberbotics/webots/R2023a/projects/appearances/protos/textures/parquetry/chequered_parquetry_occlusion.jpg"
          ]
        }
      }
      geometry Plane {
        size 1 0.025
      }
    }
  ]
  name "solid(17)"
}
Solid {
  translation -2.61378 -0.840272 0.001
  rotation 0 0 1 0.785399
  children [
    Shape {
      appearance PBRAppearance {
        baseColor 0 0 0
        roughness 1
        roughnessMap ImageTexture {
          url [
            "https://raw.githubusercontent.com/cyberbotics/webots/R2023a/projects/appearances/protos/textures/parquetry/chequered_parquetry_roughness.jpg"
          ]
        }
        metalness 0
        normalMap ImageTexture {
          url [
            "https://raw.githubusercontent.com/cyberbotics/webots/R2023a/projects/appearances/protos/textures/parquetry/chequered_parquetry_normal.jpg"
          ]
        }
        occlusionMap ImageTexture {
          url [
            "https://raw.githubusercontent.com/cyberbotics/webots/R2023a/projects/appearances/protos/textures/parquetry/chequered_parquetry_occlusion.jpg"
          ]
        }
      }
      geometry Plane {
        size 0.3 0.025
      }
    }
  ]
  name "solid(18)"
}
Solid {
  translation -2.8427 -0.856976 0.001
  rotation 0 0 -1 0.523597
  children [
    Shape {
      appearance PBRAppearance {
        baseColor 0 0 0
        roughness 1
        roughnessMap ImageTexture {
          url [
            "https://raw.githubusercontent.com/cyberbotics/webots/R2023a/projects/appearances/protos/textures/parquetry/chequered_parquetry_roughness.jpg"
          ]
        }
        metalness 0
        normalMap ImageTexture {
          url [
            "https://raw.githubusercontent.com/cyberbotics/webots/R2023a/projects/appearances/protos/textures/parquetry/chequered_parquetry_normal.jpg"
          ]
        }
        occlusionMap ImageTexture {
          url [
            "https://raw.githubusercontent.com/cyberbotics/webots/R2023a/projects/appearances/protos/textures/parquetry/chequered_parquetry_occlusion.jpg"
          ]
        }
      }
      geometry Plane {
        size 0.3 0.025
      }
    }
  ]
  name "solid(19)"
}
Solid {
  translation -2.8309 -0.398232 0.001
  rotation 0 0 -1 1.88
  children [
    Shape {
      appearance PBRAppearance {
        baseColor 0 0 0
        roughness 1
        roughnessMap ImageTexture {
          url [
            "https://raw.githubusercontent.com/cyberbotics/webots/R2023a/projects/appearances/protos/textures/parquetry/chequered_parquetry_roughness.jpg"
          ]
        }
        metalness 0
        normalMap ImageTexture {
          url [
            "https://raw.githubusercontent.com/cyberbotics/webots/R2023a/projects/appearances/protos/textures/parquetry/chequered_parquetry_normal.jpg"
          ]
        }
        occlusionMap ImageTexture {
          url [
            "https://raw.githubusercontent.com/cyberbotics/webots/R2023a/projects/appearances/protos/textures/parquetry/chequered_parquetry_occlusion.jpg"
          ]
        }
      }
      geometry Plane {
        size 0.85 0.025
      }
    }
  ]
  name "solid(20)"
}
Solid {
  translation -2.14 -0.02 0.05
  children [
    DEF box Shape {
      appearance PBRAppearance {
        baseColor 0 0.666667 0
        roughness 1
        metalness 0
      }
      geometry Box {
        size 0.05 0.035 0.05
      }
    }
  ]
  name "solid(21)"
  boundingObject USE box
  physics Physics {
  }
}
Solid {
  translation -1.3 -0.21 0.03
  children [
    DEF box Shape {
      appearance PBRAppearance {
        baseColor 0 0.666667 0
        roughness 1
        metalness 0
      }
      geometry Box {
        size 0.05 0.05 0.05
      }
    }
  ]
  name "solid(23)"
  boundingObject USE box
  physics Physics {
  }
}
Solid {
  translation -1.83 0.14 0
  children [
    DEF stn Shape {
      appearance PBRAppearance {
      }
      geometry Box {
        size 0.2 0.1 0.1
      }
    }
  ]
  name "solid(22)"
  boundingObject USE stn
  physics Physics {
  }
}
Solid {
  translation -0.256568 -0.914852 0
  rotation 0 0 1 0.785398
  children [
    DEF stn Shape {
      appearance PBRAppearance {
      }
      geometry Box {
        size 0.2 0.1 0.1
      }
    }
  ]
  name "solid(24)"
  boundingObject USE stn
  physics Physics {
  }
}
